<robot name="robot">
  <link name="base_link"> 
    <origin xyz="0 0 0" rpy="0 0 0" />
    <visual>
      <origin xyz="0 0 0" rpy="0 0 0" />
      <geometry>
        <box size="0 0 0" />
      </geometry>
      <material name="Cyan1">
        <color rgba="0 0.9 0.9 1.0" />
      </material>
    </visual>
  </link> 

  <link name="link_1">
    <origin xyz="175 0 0" rpy="0 0 0" />
    <visual>
      <origin xyz="175 0 0" rpy="0 0 0" />
      <geometry>
        <box size="350 25 0" />
      </geometry>
      <material name="Cyan1">
        <color rgba="0 0.9 0.9 1.0" />
      </material>
    </visual>  
  </link> 

  <link name="link_2"> 
    <origin xyz="140 0 0" rpy="0 0 0" />
    <visual>
      <origin xyz="140 0 0" rpy="0 0 0" />
      <geometry>
        <box size="350 25 0" />
      </geometry>
      <material name="Cyan2">
        <color rgba="1.0 0 0 1" />
      </material>
    </visual>
  </link>

  <link name="pen">
    <origin xyz="0 0 0" rpy="0 0 0" />
    <visual>
      <origin xyz="0 0 0" rpy="0 0 0" />
      <geometry>
        <box size="10 10 0" />
      </geometry>
      <material name="Cyan3">
        <color rgba="0 0 1.0 1" />
      </material>
    </visual>
  </link>

  <joint name="joint_1" type="revolute">
    <parent link="base_link"/>
    <child link="link_1"/>
    <origin xyz="0 0 0" rpy="0 0 0" />
    <axis xyz="0 0 1" />
  </joint>

  <joint name="joint_2" type="revolute">
    <parent link="link_1"/>
    <child link="link_2"/>
    <origin xyz="315 0 0" rpy="0 0 0" />
    <axis xyz="0 0 1" />
  </joint>

  <joint name="joint_3" type="revolute">
    <parent link="link_2"/>
    <child link="pen"/>
    <origin xyz="315 0 0" rpy="0 0 0" />
    <axis xyz="0 0 0" />
  </joint>
</robot>